<?xml version="1.0"?>
<!-- Revolute-Revolute Manipulator -->
<robot name="zm_robot" 

  xmlns:sensor="http://playerstage.sourceforge.net/gazebo/xmlschema/#sensor"
  xmlns:controller="http://playerstage.sourceforge.net/gazebo/xmlschema/#controller"
  xmlns:interface="http://playerstage.sourceforge.net/gazebo/xmlschema/#interface"
  xmlns:xacro="http://www.ros.org/wiki/xacro">

  <!-- Constants for robot dimensions -->

  <xacro:property name="wheel_rotationx" value="-1.5708"/>
  <xacro:property name="agv_base_h" value="0.081572" /> <!-- agv_base height -->
  <xacro:property name="wheel_before_L" value="0.25" /> <!-- wheel before L -->
  <xacro:property name="wheel_after_L" value="-0.25" /> <!-- wheel_after_L -->
  <xacro:property name="wheel_left_W" value="0.3" /> <!-- wheel left W -->
  <xacro:property name="wheel_right_W" value="-0.3" /> <!-- wheel right W -->

  <!-- <xacro:property name="mycobot_origin" value="0 0 0.006" /> -->
  <!-- <xacro:property name="prefix" value="" />  -->
  <!-- <xacro:property name="parent" value="base_link" /> -->

  <!-- ultrasound position on robot-->
  <!-- <xacro:property name="ul_left_front_x" value="0.4"/>
  <xacro:property name="ul_left_front_y" value="0.15" /> 
  <xacro:property name="ul_right_front_x" value="0.4" /> 
  <xacro:property name="ul_right_front_y" value="-0.15" />
  <xacro:property name="ul_left_rear_x" value="-0.4" />
  <xacro:property name="ul_left_rear_y" value="0.15" />
  <xacro:property name="ul_right_rear_x" value="-0.4" />
  <xacro:property name="ul_right_rear_y" value="-0.15" />
  <xacro:property name="ul_hight" value="0.03" />
  <xacro:property name="ul_front_rotation" value="0" />
  <xacro:property name="ul_rear_rotation" value="3.141592654" />
  -->

  <!-- roller position -->
  <xacro:property name="roller_1_y" value="0"/>
  <xacro:property name="roller_2_y" value="0.041781"/>
  <xacro:property name="roller_3_y" value="0.064012"/>
  <xacro:property name="roller_4_y" value="0.056291"/>
  <xacro:property name="roller_5_y" value="0.022231"/>
  <xacro:property name="roller_6_y" value="-0.022231"/>
  <xacro:property name="roller_7_y" value="-0.056291"/>
  <xacro:property name="roller_8_y" value="-0.064012"/>
  <xacro:property name="roller_9_y" value="-0.041781"/>
  <xacro:property name="roller_1_x" value="0.065"/>
  <xacro:property name="roller_2_x" value="0.049792"/>
  <xacro:property name="roller_3_x" value="0.011287"/>
  <xacro:property name="roller_4_x" value="-0.0325"/>
  <xacro:property name="roller_5_x" value="-0.06108"/>
  <xacro:property name="roller_6_x" value="-0.06108"/>
  <xacro:property name="roller_7_x" value="-0.0325"/>
  <xacro:property name="roller_8_x" value="0.011287"/>
  <xacro:property name="roller_9_x" value="0.049792"/>

  <xacro:arg name="gazebo_plugin" default="true" />
  <xacro:arg name="robot_namespace" default="" />

  <xacro:property name="width" value=".2" />

  <!-- PROPERTY LIST -->
  <!-- All units in m-kg-s-radians unit system -->
  <!-- 
  <xacro:property name="M_PI" value="3.14159" />
  <xacro:property name="SCALE_MM" value="0.001"/>
  <xacro:property name="SCALE_CM" value="0.01"/>
  -->
  <!-- Inertial macros. Units are kg*m^2 -->
  <!-- <xacro:macro name="box_inertia" params="m x y z">
    <inertia ixx="${m*(y*y+z*z)/12}" ixy = "0" ixz = "0"
      iyy="${m*(z*z+x*x)/12}" iyz = "0"
      izz="${m*(x*x+y*y)/12}" /> 
  </xacro:macro>
  <xacro:macro name="cylinder_inertia" params="m r h">
    <inertia ixx="${m*(3*r*r+h*h)/12}" ixy="0" ixz="0"
      iyy="${m*(3*r*r+h*h)/12}" iyz="0"
      izz="${m*r*r/2}" />
  </xacro:macro>
  <xacro:macro name="sphere_inertia" params="m r">
    <inertia ixx="${m*r*r/5}" ixy="0" ixz="0"
      iyy="${m*r*r/5}" iyz="0"
      izz="${m*r*r/5}" /> 
  </xacro:macro>
  -->


  <!-- PROPERTY LIST -->
  <!-- All units in m-kg-s-radians unit system -->
  <xacro:property name="M_PI" value="3.14159" />
  <xacro:property name="SCALE_MM" value="0.001"/>
  <xacro:property name="SCALE_CM" value="0.01"/>
  <xacro:property name="joint_velocity_limit" value="1.0" />

  <!-- Import Rviz colors -->
  <xacro:include filename="$(find zm_robot_description)/urdf/materials.xacro" />

  <!-- Import rollor and wheel -->
  <xacro:include filename="$(find zm_robot_description)/urdf/zm_robot_roller.urdf.xacro"/>
  <xacro:include filename="$(find zm_robot_description)/urdf/zm_robot_wheel_LF.urdf.xacro"/>
  <xacro:include filename="$(find zm_robot_description)/urdf/zm_robot_wheel_LR.urdf.xacro"/>
  <xacro:include filename="$(find zm_robot_description)/urdf/zm_robot_wheel_RF.urdf.xacro"/>
  <xacro:include filename="$(find zm_robot_description)/urdf/zm_robot_wheel_RR.urdf.xacro"/>
  <xacro:include filename="$(find zm_robot_description)/urdf/common.xacro" />
  <!--<xacro:include filename="$(find zm_robot_description)/urdf/mycobot.xacro" />-->
  
  <!-- Import Ultrasound -->
  <!-- <xacro:include filename="$(find zm_robot_description)/urdf/zm_robot_ultrasound.urdf.xacro"/> -->

  <!-- Import Plugin -->
  <xacro:include filename="$(find zm_robot_description)/urdf/zm_robot_plugin.gazebo"/>
  <!-- <xacro:include filename="$(find zm_robot_description)/urdf/mycobot_plugin.gazebo"/> -->


 <!-- ************ MOBILE BASE ************* -->
  
  <!-- Used for fixing robot to Gazebo 'base_link' -->
  <link name="base_footprint"/>

  <joint name="base_joint" type="fixed">
    <parent link="base_footprint"/>
    <child link="base_link"/>
    <origin xyz="0 0 ${agv_base_h}" rpy="0 0 0"/>
  </joint>

  <!-- Base Link -->
  <link name="base_link">
    <collision>
      <origin xyz="0 0 0" rpy="0 0 0"/>
      <geometry>
        <mesh filename="package://zm_robot_description/meshes/agv_base.stl" scale="0.01 0.01 0.01"/>
      </geometry>
    </collision>

    <visual>
      <origin xyz="0 0 0" rpy="0 0 0"/>
      <geometry>
        <mesh filename="package://zm_robot_description/meshes/agv_base.stl" scale="0.01 0.01 0.01"/>
      </geometry>
      <material name="orange"/>
    </visual>

    <inertial>
      <origin xyz="0 0 0" rpy="0 0 0"/>
      <mass value="29.964"/>
      <inertia ixx="0.892684320" ixy="0.0" ixz="0.0"
	             iyy="1.966612482" iyz="0.0"
	             izz="2.677227828"/>
    </inertial>
  </link>

  <!-- sick LiDAR 0 -->
  <!-- <joint name="sick_lidar0_joint" type="fixed">
    <parent link="base_link"/>
    <child link="sick_lidar0"/>
    <origin xyz="0.33 0.175 0.195722" rpy="0 0 0.7854"/>
  </joint> -->

  <!-- <link name="sick_lidar0">
    <collision>
      <origin xyz="0 0 0" rpy="0 0 0"/>
      <geometry>
        <mesh filename="package://zm_robot_description/meshes/sick_s30b.stl" scale="0.01 0.01 0.01"/>
      </geometry>
    </collision>

    <visual>
      <origin xyz="0 0 0" rpy="0 0 0"/>
      <geometry>
        <mesh filename="package://zm_robot_description/meshes/sick_s30b.stl" scale="0.01 0.01 0.01"/>
      </geometry>
      <material name="green"/>
    </visual>

    <inertial>
      <origin xyz="0 0 0" rpy="0 0 0"/>
      <mass value="1.2"/>
      <inertia ixx="0.0001" ixy="0.0" ixz="0.0"
	             iyy="0.0001" iyz="0.0"
	             izz="0.0001"/>
      </inertial>
  </link> -->

  <!-- sick LiDAR 1 -->
  <!-- <joint name="sick_lidar1_joint" type="fixed">
    <parent link="base_link"/>
    <child link="sick_lidar1"/>
    <origin xyz="-0.33 -0.175 0.195722" rpy="0 0 -2.35619"/>
  </joint>

  <link name="sick_lidar1">
    <collision>
      <origin xyz="0 0 0" rpy="0 0 0"/>
      <geometry>
        <mesh filename="package://zm_robot_description/meshes/sick_s30b.stl" scale="0.01 0.01 0.01"/>
      </geometry>
    </collision>

    <visual>
      <origin xyz="0 0 0" rpy="0 0 0"/>
      <geometry>
        <mesh filename="package://zm_robot_description/meshes/sick_s30b.stl" scale="0.01 0.01 0.01"/>
      </geometry>
      <material name="green"/>
    </visual>

    <inertial>
      <origin xyz="0 0 0" rpy="0 0 0"/>
      <mass value="1.2"/>
      <inertia ixx="0.0001" ixy="0.0" ixz="0.0"
	             iyy="0.0001" iyz="0.0"
	             izz="0.0001"/>
      </inertial>
  </link> -->

  <!-- kinect V2 -->
  <!-- <joint name="kinect_v2_joint " type="fixed">
    <parent link="base_link"/>
    <child link="kinect_v2"/>
    <origin xyz="0.297 -0.05 0.122015" rpy="0 0 0"/>
    <axis xyz="0 0 1"/>
  </joint>

  <link name="kinect_v2">
    <collision>
      <origin xyz="0 0 0" rpy="0 0 0"/>
      <geometry>
	      <mesh filename="package://zm_robot_description/meshes/kinect_v2.stl" scale="0.01 0.01 0.01"/>
      </geometry>
    </collision>

    <visual>
      <origin xyz="0 0 0" rpy="0 0 0"/>
      <geometry>
	      <mesh filename="package://zm_robot_description/meshes/kinect_v2.stl" scale="0.01 0.01 0.01"/>
      </geometry>
      <material name="black"/>
    </visual>

    <inertial>
      <origin xyz="0 0 0" rpy="0 0 0"/>
      <mass value="0.5"/>
      <inertia ixx="0.00005" ixy="0.0" ixz="0.0"
	             iyy="0.00005" iyz="0.0"
	             izz="0.00005"/>
    </inertial>
  </link> -->

  <!-- IMU -->
  <joint name="IMU_joint " type="fixed">
    <parent link="base_link"/>
    <child link="IMU_sensor"/>
    <origin xyz="0 0 0.08" rpy="0 0 0"/>
    <axis xyz="0 0 1"/>
  </joint>

  <link name="IMU_sensor">
    <collision>
      <origin xyz="0 0 0" rpy="0 0 0"/>
      <geometry>
	      <mesh filename="package://zm_robot_description/meshes/IMU_sensor.stl" scale="0.01 0.01 0.01"/>
      </geometry>
    </collision>

    <visual>
      <origin xyz="0 0 0" rpy="0 0 0"/>
      <geometry>
	      <mesh filename="package://zm_robot_description/meshes/IMU_sensor.stl" scale="0.01 0.01 0.01"/>
      </geometry>
      <material name="red"/>
    </visual>

    <inertial>
      <origin xyz="0 0 0" rpy="0 0 0"/>
      <mass value="0.5"/>
      <inertia ixx="0.00005" ixy="0.0" ixz="0.0"
	             iyy="0.00005" iyz="0.0"
	            izz="0.00005"/>
    </inertial>
  </link>

  <!--zm robot LR wheel-->
  <xacro:zm_wheel_v1 prefix="1" parent="base_link" origin_x="${wheel_after_L}" origin_y="${wheel_left_W}" rotation_x="${wheel_rotationx}">
  </xacro:zm_wheel_v1>

  <!--zm robot LR rollor-->
  <xacro:zm_roller_v0 prefix="roller_1_1" parent="wheel_1" origin_x="${roller_1_y}" origin_y="${roller_1_x}"
                                                           rotation_x="0.7854" rotation_z="1.5708">
  </xacro:zm_roller_v0>

  <xacro:zm_roller_v0 prefix="roller_1_2" parent="wheel_1" origin_x="${roller_2_y}" origin_y="${roller_2_x}"
                                                           rotation_x="0.7854" rotation_z="0.8727">
  </xacro:zm_roller_v0>

  <xacro:zm_roller_v0 prefix="roller_1_3" parent="wheel_1" origin_x="${roller_3_y}" origin_y="${roller_3_x}"
                                                           rotation_x="0.7854" rotation_z="0.1746">
  </xacro:zm_roller_v0>

  <xacro:zm_roller_v0 prefix="roller_1_4" parent="wheel_1" origin_x="${roller_4_y}" origin_y="${roller_4_x}"
                                                           rotation_x="0.7854" rotation_z="-0.5235">
  </xacro:zm_roller_v0>

  <xacro:zm_roller_v0 prefix="roller_1_5" parent="wheel_1" origin_x="${roller_5_y}" origin_y="${roller_5_x}"
                                                           rotation_x="0.7854" rotation_z="-1.2216">
  </xacro:zm_roller_v0>

  <xacro:zm_roller_v0 prefix="roller_1_6" parent="wheel_1" origin_x="${roller_6_y}" origin_y="${roller_6_x}"
                                                           rotation_x="0.7854" rotation_z="4.3632">
  </xacro:zm_roller_v0>

  <xacro:zm_roller_v0 prefix="roller_1_7" parent="wheel_1" origin_x="${roller_7_y}" origin_y="${roller_7_x}"
                                                           rotation_x="0.7854" rotation_z="3.6651">
  </xacro:zm_roller_v0>

  <xacro:zm_roller_v0 prefix="roller_1_8" parent="wheel_1" origin_x="${roller_8_y}" origin_y="${roller_8_x}"
                                                           rotation_x="0.7854" rotation_z="2.967">
  </xacro:zm_roller_v0>

  <xacro:zm_roller_v0 prefix="roller_1_9" parent="wheel_1" origin_x="${roller_9_y}" origin_y="${roller_9_x}"
                                                           rotation_x="0.7854" rotation_z="2.2689">
  </xacro:zm_roller_v0>

  <!--zm robot LF wheel-->
  <xacro:zm_wheel_v2 prefix="2" parent="base_link" origin_x="${wheel_before_L}" origin_y="${wheel_left_W}" rotation_x="${wheel_rotationx}">
  </xacro:zm_wheel_v2>

  <!--zm robot LF rollor-->
  <xacro:zm_roller_v0 prefix="roller_2_1" parent="wheel_2" origin_x="${roller_1_x}" origin_y="${roller_1_y}"
                                                           rotation_x="-0.7854" rotation_z="0">
  </xacro:zm_roller_v0>

  <xacro:zm_roller_v0 prefix="roller_2_2" parent="wheel_2" origin_x="${roller_2_x}" origin_y="${roller_2_y}"
                                                           rotation_x="-0.7854" rotation_z="0.6981">
  </xacro:zm_roller_v0>

  <xacro:zm_roller_v0 prefix="roller_2_3" parent="wheel_2" origin_x="${roller_3_x}" origin_y="${roller_3_y}"
                                                           rotation_x="-0.7854" rotation_z="1.3962">
  </xacro:zm_roller_v0>

  <xacro:zm_roller_v0 prefix="roller_2_4" parent="wheel_2" origin_x="${roller_4_x}" origin_y="${roller_4_y}"
                                                           rotation_x="-0.7854" rotation_z="2.0943">
  </xacro:zm_roller_v0>

  <xacro:zm_roller_v0 prefix="roller_2_5" parent="wheel_2" origin_x="${roller_5_x}" origin_y="${roller_5_y}"
                                                           rotation_x="-0.7854" rotation_z="2.7924">
  </xacro:zm_roller_v0>

  <xacro:zm_roller_v0 prefix="roller_2_6" parent="wheel_2" origin_x="${roller_6_x}" origin_y="${roller_6_y}"
                                                           rotation_x="-0.7854" rotation_z="-2.7924">
  </xacro:zm_roller_v0>

  <xacro:zm_roller_v0 prefix="roller_2_7" parent="wheel_2" origin_x="${roller_7_x}" origin_y="${roller_7_y}"
                                                           rotation_x="-0.7854" rotation_z="-2.0943">
  </xacro:zm_roller_v0>

  <xacro:zm_roller_v0 prefix="roller_2_8" parent="wheel_2" origin_x="${roller_8_x}" origin_y="${roller_8_y}"
                                                           rotation_x="-0.7854" rotation_z="-1.3962">
  </xacro:zm_roller_v0>

  <xacro:zm_roller_v0 prefix="roller_2_9" parent="wheel_2" origin_x="${roller_9_x}" origin_y="${roller_9_y}"
                                                           rotation_x="-0.7854" rotation_z="-0.6981">
  </xacro:zm_roller_v0>

  <!--zm robot RF wheel-->
  <xacro:zm_wheel_v3 prefix="3" parent="base_link" origin_x="${wheel_before_L}" origin_y="${wheel_right_W}" rotation_x="${wheel_rotationx}">
  </xacro:zm_wheel_v3>

  <!--zm robot RF rollor-->
  <xacro:zm_roller_v0 prefix="roller_3_1" parent="wheel_3" origin_x="${roller_1_y}" origin_y="${roller_1_x}"
                                                           rotation_x="0.7854" rotation_z="1.5708">
  </xacro:zm_roller_v0>

  <xacro:zm_roller_v0 prefix="roller_3_2" parent="wheel_3" origin_x="${roller_2_y}" origin_y="${roller_2_x}"
                                                           rotation_x="0.7854" rotation_z="0.8727">
  </xacro:zm_roller_v0>

  <xacro:zm_roller_v0 prefix="roller_3_3" parent="wheel_3" origin_x="${roller_3_y}" origin_y="${roller_3_x}"
                                                           rotation_x="0.7854" rotation_z="0.1746">
  </xacro:zm_roller_v0>

  <xacro:zm_roller_v0 prefix="roller_3_4" parent="wheel_3" origin_x="${roller_4_y}" origin_y="${roller_4_x}"
                                                           rotation_x="0.7854" rotation_z="-0.5235">
  </xacro:zm_roller_v0>

  <xacro:zm_roller_v0 prefix="roller_3_5" parent="wheel_3" origin_x="${roller_5_y}" origin_y="${roller_5_x}"
                                                           rotation_x="0.7854" rotation_z="-1.2216">
  </xacro:zm_roller_v0>

  <xacro:zm_roller_v0 prefix="roller_3_6" parent="wheel_3" origin_x="${roller_6_y}" origin_y="${roller_6_x}"
                                                           rotation_x="0.7854" rotation_z="4.3632">
  </xacro:zm_roller_v0>

  <xacro:zm_roller_v0 prefix="roller_3_7" parent="wheel_3" origin_x="${roller_7_y}" origin_y="${roller_7_x}"
                                                           rotation_x="0.7854" rotation_z="3.6651">
  </xacro:zm_roller_v0>

  <xacro:zm_roller_v0 prefix="roller_3_8" parent="wheel_3" origin_x="${roller_8_y}" origin_y="${roller_8_x}"
                                                           rotation_x="0.7854" rotation_z="2.967">
  </xacro:zm_roller_v0>

  <xacro:zm_roller_v0 prefix="roller_3_9" parent="wheel_3" origin_x="${roller_9_y}" origin_y="${roller_9_x}"
                                                           rotation_x="0.7854" rotation_z="2.2689">
  </xacro:zm_roller_v0>

  <!--zm robot RR wheel-->
  <xacro:zm_wheel_v4 prefix="4" parent="base_link" origin_x="${wheel_after_L}" origin_y="${wheel_right_W}" rotation_x="${wheel_rotationx}">
  </xacro:zm_wheel_v4>

  <!--zm robot RR rollor-->
  <xacro:zm_roller_v0 prefix="roller_4_1" parent="wheel_4" origin_x="${roller_1_x}" origin_y="${roller_1_y}"
                                                           rotation_x="-0.7854" rotation_z="0">
  </xacro:zm_roller_v0>

  <xacro:zm_roller_v0 prefix="roller_4_2" parent="wheel_4" origin_x="${roller_2_x}" origin_y="${roller_2_y}"
                                                           rotation_x="-0.7854" rotation_z="0.6981">
  </xacro:zm_roller_v0>

  <xacro:zm_roller_v0 prefix="roller_4_3" parent="wheel_4" origin_x="${roller_3_x}" origin_y="${roller_3_y}"
                                                           rotation_x="-0.7854" rotation_z="1.3962">
  </xacro:zm_roller_v0>

  <xacro:zm_roller_v0 prefix="roller_4_4" parent="wheel_4" origin_x="${roller_4_x}" origin_y="${roller_4_y}"
                                                           rotation_x="-0.7854" rotation_z="2.0943">
  </xacro:zm_roller_v0>

  <xacro:zm_roller_v0 prefix="roller_4_5" parent="wheel_4" origin_x="${roller_5_x}" origin_y="${roller_5_y}"
                                                           rotation_x="-0.7854" rotation_z="2.7924">
  </xacro:zm_roller_v0>

  <xacro:zm_roller_v0 prefix="roller_4_6" parent="wheel_4" origin_x="${roller_6_x}" origin_y="${roller_6_y}"
                                                           rotation_x="-0.7854" rotation_z="-2.7924">
  </xacro:zm_roller_v0>

  <xacro:zm_roller_v0 prefix="roller_4_7" parent="wheel_4" origin_x="${roller_7_x}" origin_y="${roller_7_y}"
                                                           rotation_x="-0.7854" rotation_z="-2.0943">
  </xacro:zm_roller_v0>

  <xacro:zm_roller_v0 prefix="roller_4_8" parent="wheel_4" origin_x="${roller_8_x}" origin_y="${roller_8_y}"
                                                           rotation_x="-0.7854" rotation_z="-1.3962">
  </xacro:zm_roller_v0>

  <xacro:zm_roller_v0 prefix="roller_4_9" parent="wheel_4" origin_x="${roller_9_x}" origin_y="${roller_9_y}"
                                                           rotation_x="-0.7854" rotation_z="-0.6981">
  </xacro:zm_roller_v0>

  <!-- Wheel -->
  <xacro:wheel_gazebo_v0 prefix="1"/>
  <xacro:wheel_gazebo_v0 prefix="2"/>
  <xacro:wheel_gazebo_v0 prefix="3"/>
  <xacro:wheel_gazebo_v0 prefix="4"/>

  <!-- Rollor -->
  <xacro:roller_gazebo_v0 prefix="roller_1_1"/>
  <xacro:roller_gazebo_v0 prefix="roller_1_2"/>
  <xacro:roller_gazebo_v0 prefix="roller_1_3"/>
  <xacro:roller_gazebo_v0 prefix="roller_1_4"/>
  <xacro:roller_gazebo_v0 prefix="roller_1_5"/>
  <xacro:roller_gazebo_v0 prefix="roller_1_6"/>
  <xacro:roller_gazebo_v0 prefix="roller_1_7"/>
  <xacro:roller_gazebo_v0 prefix="roller_1_8"/>
  <xacro:roller_gazebo_v0 prefix="roller_1_9"/>

  <xacro:roller_gazebo_v0 prefix="roller_2_1"/>
  <xacro:roller_gazebo_v0 prefix="roller_2_2"/>
  <xacro:roller_gazebo_v0 prefix="roller_2_3"/>
  <xacro:roller_gazebo_v0 prefix="roller_2_4"/>
  <xacro:roller_gazebo_v0 prefix="roller_2_5"/>
  <xacro:roller_gazebo_v0 prefix="roller_2_6"/>
  <xacro:roller_gazebo_v0 prefix="roller_2_7"/>
  <xacro:roller_gazebo_v0 prefix="roller_2_8"/>
  <xacro:roller_gazebo_v0 prefix="roller_2_9"/>

  <xacro:roller_gazebo_v0 prefix="roller_3_1"/>
  <xacro:roller_gazebo_v0 prefix="roller_3_2"/>
  <xacro:roller_gazebo_v0 prefix="roller_3_3"/>
  <xacro:roller_gazebo_v0 prefix="roller_3_4"/>
  <xacro:roller_gazebo_v0 prefix="roller_3_5"/>
  <xacro:roller_gazebo_v0 prefix="roller_3_6"/>
  <xacro:roller_gazebo_v0 prefix="roller_3_7"/>
  <xacro:roller_gazebo_v0 prefix="roller_3_8"/>
  <xacro:roller_gazebo_v0 prefix="roller_3_9"/>

  <xacro:roller_gazebo_v0 prefix="roller_4_1"/>
  <xacro:roller_gazebo_v0 prefix="roller_4_2"/>
  <xacro:roller_gazebo_v0 prefix="roller_4_3"/>
  <xacro:roller_gazebo_v0 prefix="roller_4_4"/>
  <xacro:roller_gazebo_v0 prefix="roller_4_5"/>
  <xacro:roller_gazebo_v0 prefix="roller_4_6"/>
  <xacro:roller_gazebo_v0 prefix="roller_4_7"/>
  <xacro:roller_gazebo_v0 prefix="roller_4_8"/>
  <xacro:roller_gazebo_v0 prefix="roller_4_9"/>

  <!-- Rollor -->
  <xacro:roller_trans_v0 prefix="roller_1_1"/>
  <xacro:roller_trans_v0 prefix="roller_1_2"/>
  <xacro:roller_trans_v0 prefix="roller_1_3"/>
  <xacro:roller_trans_v0 prefix="roller_1_4"/>
  <xacro:roller_trans_v0 prefix="roller_1_5"/>
  <xacro:roller_trans_v0 prefix="roller_1_6"/>
  <xacro:roller_trans_v0 prefix="roller_1_7"/>
  <xacro:roller_trans_v0 prefix="roller_1_8"/>
  <xacro:roller_trans_v0 prefix="roller_1_9"/>

  <xacro:roller_trans_v0 prefix="roller_2_1"/>
  <xacro:roller_trans_v0 prefix="roller_2_2"/>
  <xacro:roller_trans_v0 prefix="roller_2_3"/>
  <xacro:roller_trans_v0 prefix="roller_2_4"/>
  <xacro:roller_trans_v0 prefix="roller_2_5"/>
  <xacro:roller_trans_v0 prefix="roller_2_6"/>
  <xacro:roller_trans_v0 prefix="roller_2_7"/>
  <xacro:roller_trans_v0 prefix="roller_2_8"/>
  <xacro:roller_trans_v0 prefix="roller_2_9"/>

  <xacro:roller_trans_v0 prefix="roller_3_1"/>
  <xacro:roller_trans_v0 prefix="roller_3_2"/>
  <xacro:roller_trans_v0 prefix="roller_3_3"/>
  <xacro:roller_trans_v0 prefix="roller_3_4"/>
  <xacro:roller_trans_v0 prefix="roller_3_5"/>
  <xacro:roller_trans_v0 prefix="roller_3_6"/>
  <xacro:roller_trans_v0 prefix="roller_3_7"/>
  <xacro:roller_trans_v0 prefix="roller_3_8"/>
  <xacro:roller_trans_v0 prefix="roller_3_9"/>

  <xacro:roller_trans_v0 prefix="roller_4_1"/>
  <xacro:roller_trans_v0 prefix="roller_4_2"/>
  <xacro:roller_trans_v0 prefix="roller_4_3"/>
  <xacro:roller_trans_v0 prefix="roller_4_4"/>
  <xacro:roller_trans_v0 prefix="roller_4_5"/>
  <xacro:roller_trans_v0 prefix="roller_4_6"/>
  <xacro:roller_trans_v0 prefix="roller_4_7"/>
  <xacro:roller_trans_v0 prefix="roller_4_8"/>
  <xacro:roller_trans_v0 prefix="roller_4_9"/>

  <!-- ultrasound -->
  <!-- <xacro:zm_ultrasound prefix="1" parent="base_link" origin_x="${ul_left_front_x}" origin_y="${ul_left_front_y}" 
                                                     origin_z="${ul_hight}" rotation_z="${ul_front_rotation}">
  </xacro:zm_ultrasound>

  <xacro:zm_ultrasound prefix="2" parent="base_link" origin_x="${ul_right_front_x}" origin_y="${ul_right_front_y}" 
                                                     origin_z="${ul_hight}" rotation_z="${ul_front_rotation}">
  </xacro:zm_ultrasound>

  <xacro:zm_ultrasound prefix="3" parent="base_link" origin_x="${ul_left_rear_x}" origin_y="${ul_left_rear_y}" 
                                                     origin_z="${ul_hight}" rotation_z="${ul_rear_rotation}">
  </xacro:zm_ultrasound>

  <xacro:zm_ultrasound prefix="4" parent="base_link" origin_x="${ul_right_rear_x}" origin_y="${ul_right_rear_y}" 
                                                     origin_z="${ul_hight}" rotation_z="${ul_rear_rotation}">
  </xacro:zm_ultrasound>
  -->
  
  <!--********** MYCOBOT ARM ************ --> 
  
  <joint name="mycobot_base_joint" type="fixed">
    <parent link="base_link" />
    <child link="link_1" />
    <origin xyz="0 0 0.09" rpy="0 0 0" />
    <axis xyz="0 0 1"/> 
  </joint>
    
  <link name="link_1">
    <visual>
      <geometry>
             <mesh filename="package://zm_robot_description/meshes/link1.dae" scale="1 1 1" />
      </geometry>
      <origin xyz="0 0 0" rpy="0 0 0" />
    </visual>
    <collision>
      <geometry>
             <mesh filename="package://zm_robot_description/meshes/link1.stl" scale="1 1 1"/>
      </geometry>
      <origin xyz="0 0 0" rpy="0 0 0" />
    </collision>
    <inertial>
      <origin xyz="0 0 0.035" rpy="0 0 0" />
      <mass value="1.0" />       
      <xacro:cylinder_inertia m="1.0" r="0.05" h="0.07" />
    </inertial>
  </link>


  <joint name="joint_1" type="revolute">
    <axis xyz="0 0 1" />
    <limit effort="10.0" lower="-${M_PI}" upper="${M_PI}" velocity="${joint_velocity_limit}" />
    <parent link="link_1" />
    <child link="link_2" />
    <origin xyz="0 0 0.0706" rpy="0 0 0" />
    <dynamics damping="1.0e-6" friction="2.0e-1" />
  </joint>
 
  <link name="link_2">
    <visual>
      <geometry>
          <mesh filename="package://zm_robot_description/meshes/link2.dae" scale="1 1 1"/>
      </geometry>
      <origin xyz="0 0 0" rpy="0 0 0" />
    </visual>
    <collision>
      <geometry>
          <mesh filename="package://zm_robot_description/meshes/link2.stl" scale="1 1 1"/>
      </geometry>
      <origin xyz="0 0 0" rpy="0 0 0" />
    </collision>
    <inertial>
      <origin xyz="0 0 0.04" rpy="0 0 0" />
      <mass value="0.2" />
      <xacro:cylinder_inertia m="0.2" r="0.025" h="0.08" />
    </inertial>
  </link>

  <joint name="joint_2" type="revolute">
    <axis xyz="0 1 0" />
    <limit effort="10.0" lower="-${M_PI}" upper="${M_PI}" velocity="${joint_velocity_limit}" />
    <parent link="link_2" />
    <child link="link_3" />
    <origin xyz="0 0.03256 0.05976" rpy="0 0 0" />
    <dynamics damping="1.0e-6" friction="2.0e-1" />
  </joint>
  
  <link name="link_3">
      <visual>
        <geometry>
          <mesh filename="package://zm_robot_description/meshes/link3.dae" scale="1 1 1"/>
        </geometry>
        <origin xyz="0 0 0" rpy="0 0 0" />
      </visual>
      <collision>
        <geometry>
          <mesh filename="package://zm_robot_description/meshes/link3.stl" scale="1 1 1"/>
        </geometry>
        <origin xyz="0 0 0" rpy="0 0 0" />
      </collision>
      <inertial>
        <origin xyz="0 0.03 0.06" rpy="0 0 0" />
        <mass value="0.4" />
        <xacro:cylinder_inertia m="0.4" r="0.025" h="0.155" />
      </inertial>
    </link>

    <joint name="joint_3" type="revolute">
      <axis xyz="0 1 0" />
      <limit effort="10.0" lower="-${M_PI}" upper="${M_PI}" velocity="${joint_velocity_limit}" />
      <parent link="link_3" />
      <child link="link_4" />
      <origin xyz=" 0 0 0.1104" rpy="0 0 0" />
      <dynamics damping="1.0e-6" friction="2.0e-1" />
    </joint>

    <link name="link_4">
      <visual>
        <geometry>
          <mesh filename="package://zm_robot_description/meshes/link4.dae" scale="1 1 1"/>
        </geometry>
        <origin xyz="0 0 0" rpy="0 0 0" />
      </visual>
      <collision>
        <geometry>
          <mesh filename="package://zm_robot_description/meshes/link4.stl" scale="1 1 1"/>
        </geometry>
        <origin xyz="0 0 0" rpy="0 0 0" />
      </collision>
      <inertial>
        <origin xyz="0 -0.03 0.05" rpy="0 0 0" />
        <mass value="0.35" />
        <xacro:cylinder_inertia m="0.35" r="0.022" h="0.137" />
      </inertial>
    </link>

    <joint name="joint_4" type="revolute">
      <axis xyz="0 1 0" />
      <limit effort="10.0" lower="-${M_PI}" upper="${M_PI}" velocity="${joint_velocity_limit}" />
      <parent link="link_4" />
      <child link="link_5" />
      <origin xyz="0 0 0.0965" rpy="0 0 0" />
      <dynamics damping="1.0e-6" friction="2.0e-1" />
    </joint>

    <link name="link_5">
      <visual>
        <geometry>
          <mesh filename="package://zm_robot_description/meshes/link5.dae" scale="1 1 1"/>
        </geometry>
        <origin xyz="0 0 0" rpy="0 0 0" />
      </visual>
      <collision>
        <geometry>
          <mesh filename="package://zm_robot_description/meshes/link5.stl" scale="1 1 1"/>
        </geometry>
        <origin xyz="0 0 0" rpy="0 0 0" />
      </collision>
      <inertial>
        <origin xyz="0 0.03 0.01" rpy="0 0 0" />
        <mass value="0.2" />
        <xacro:cylinder_inertia m="0.2" r="0.025" h="0.05" />
      </inertial>
    </link>

    <joint name="joint_5" type="revolute">
      <axis xyz="0 0 1" />
      <limit effort="10.0" lower="-${M_PI}" upper="${M_PI}" velocity="${joint_velocity_limit}" />
      <parent link="link_5" />
      <child link="link_6" />
      <origin xyz="0 0.0335 0.034" rpy="0 0 0" />
      <dynamics damping="1.0e-6" friction="2.0e-1" />
    </joint>

    <link name="link_6">
      <visual>
        <geometry>
          <mesh filename="package://zm_robot_description/meshes/link6.dae" scale="1 1 1"/>
        </geometry>
        <origin xyz="0 0 0 " rpy="0 0 0" />
      </visual>
      <collision>
        <geometry>
          <mesh filename="package://zm_robot_description/meshes/link6.stl" scale="1 1 1"/>
        </geometry>
        <origin xyz="0 0 0" rpy="0 0 0" />
      </collision>
      <inertial>
        <origin xyz="0 0 0.037" rpy="0 0 0" />
        <mass value="0.5" />
        <xacro:cylinder_inertia m="0.5" r="0.025" h="0.06" />
      </inertial>
    </link>

    <joint name="joint_6" type="revolute">
      <axis xyz="1 0 0" />
      <limit effort="10.0" lower="-${M_PI}" upper="${M_PI}" velocity="${joint_velocity_limit}" />
      <parent link="link_6" />
      <child link="link_6_flange" />
      <origin xyz="-0.035 0 0.03792" rpy="0 0 0" />
      <dynamics damping="1.0e-6" friction="2.0e-1" />
    </joint> 
    
    <link name="link_6_flange">
      <visual>
        <geometry>
          <mesh filename="package://zm_robot_description/meshes/link7.dae" scale="1 1 1"/>
        </geometry>
        <origin xyz="0 0 0" rpy="0 0 0" />
      </visual>
      <collision>
        <geometry>
          <cylinder length="0.0137" radius="0.0192" />
        </geometry>
        <origin xyz="-0.00685 0 0" rpy="0 -${M_PI/2} 0" />
      </collision>
      <inertial>
        <origin xyz="-0.005 0 0" rpy="0 -${M_PI/2} 0" />
        <mass value="0.1" />
        <xacro:cylinder_inertia m="0.1" r="0.02" h="0.01" />
      </inertial>
    </link>
    
    
    <!-- for gazebo simulation -->
    
    <xacro:if value="$(arg gazebo_plugin)">
      <transmission name="joint_1_trans">
        <provideFeedback>true</provideFeedback>
        <implicitSpringDamper>0</implicitSpringDamper>
        <motorTorqueConstant>0.418</motorTorqueConstant>
        <type>transmission_interface/SimpleTransmission</type>
        <joint name="joint_1">
          <hardwareInterface>hardware_interface/PositionJointInterface</hardwareInterface>
        </joint>
        <actuator name="joint_1_motor">
          <hardwareInterface>hardware_interface/PositionJointInterface</hardwareInterface>
          <mechanicalReduction>1</mechanicalReduction>
        </actuator>
      </transmission>
      <transmission name="joint_2_trans">
        <provideFeedback>true</provideFeedback>
        <implicitSpringDamper>0</implicitSpringDamper>
        <motorTorqueConstant>0.418</motorTorqueConstant>
        <type>transmission_interface/SimpleTransmission</type>
        <joint name="joint_2">
          <hardwareInterface>hardware_interface/PositionJointInterface</hardwareInterface>
        </joint>
        <actuator name="joint_2_motor">
          <hardwareInterface>hardware_interface/PositionJointInterface</hardwareInterface>
          <mechanicalReduction>1</mechanicalReduction>
        </actuator>
      </transmission>
      <transmission name="joint_3_trans">
        <provideFeedback>true</provideFeedback>
        <implicitSpringDamper>0</implicitSpringDamper>
        <motorTorqueConstant>0.418</motorTorqueConstant>
        <type>transmission_interface/SimpleTransmission</type>
        <joint name="joint_3">
          <hardwareInterface>hardware_interface/PositionJointInterface</hardwareInterface>
        </joint>
        <actuator name="joint_3_motor">
          <hardwareInterface>hardware_interface/PositionJointInterface</hardwareInterface>
          <mechanicalReduction>1</mechanicalReduction>
        </actuator>
      </transmission>
      <transmission name="joint_4_trans">
        <provideFeedback>true</provideFeedback>
        <implicitSpringDamper>0</implicitSpringDamper>
        <motorTorqueConstant>0.418</motorTorqueConstant>
        <type>transmission_interface/SimpleTransmission</type>
        <joint name="mycobot_joint_4">
          <hardwareInterface>hardware_interface/PositionJointInterface</hardwareInterface>
        </joint>
        <actuator name="joint_4_motor">
          <hardwareInterface>hardware_interface/PositionJointInterface</hardwareInterface>
          <mechanicalReduction>1</mechanicalReduction>
        </actuator>
      </transmission>
      <transmission name="joint_5_trans">
        <provideFeedback>true</provideFeedback>
        <implicitSpringDamper>0</implicitSpringDamper>
        <motorTorqueConstant>0.418</motorTorqueConstant>
        <type>transmission_interface/SimpleTransmission</type>
        <joint name="joint_5">
          <hardwareInterface>hardware_interface/PositionJointInterface</hardwareInterface>
        </joint>
        <actuator name="joint_5_motor">
          <hardwareInterface>hardware_interface/PositionJointInterface</hardwareInterface>
          <mechanicalReduction>1</mechanicalReduction>
        </actuator>
      </transmission>
      <transmission name="joint_6_trans">
        <provideFeedback>true</provideFeedback>
        <implicitSpringDamper>0</implicitSpringDamper>
        <motorTorqueConstant>0.418</motorTorqueConstant>
        <type>transmission_interface/SimpleTransmission</type>
        <joint name="joint_6">
          <hardwareInterface>hardware_interface/PositionJointInterface</hardwareInterface>
        </joint>
        <actuator name="joint_6_motor">
          <hardwareInterface>hardware_interface/PositionJointInterface</hardwareInterface>
          <mechanicalReduction>1</mechanicalReduction>
        </actuator>
      </transmission>
    </xacro:if>
    
  <xacro:if value="$(arg gazebo_plugin)">
    <gazebo>
      <plugin name="gazebo_ros_control" filename="libgazebo_ros_control.so">
        <robotNamespace>$(arg robot_namespace)</robotNamespace>
        <robotSimType>gazebo_ros_control/DefaultRobotHWSim</robotSimType>
        <legacyModeNS>false</legacyModeNS>
      </plugin>
    </gazebo>
  </xacro:if>
  

  <!-- *********** TEST ************ -->
  <!-- It conflicts with base robot gazebo plugin while we can move the base. 
       Without the Gazebo Plugin, the robot will fall off.
       Rostopic list does not show topics related to arm.
  -->
  <!-- Used for fixing robot to Gazebo 'base_link' -->
  <!-- 
  <joint name="base_to_arm" type="fixed">
     <axis xyz="0 0 1" />
     <parent link="base_link" />
     <child link="arm_base_link" />
  </joint>   
  
  
  <link name="arm_base_link">
    <visual>
      <geometry>
        <mesh filename="package://zm_robot_description/meshes/base_link.dae" />
      </geometry>
      <origin xyz="0 0 0" rpy="0 0 0" />
    </visual>
    <collision>
      <geometry>
        <mesh filename="package://zm_robot_description/meshes/base_link.stl" />
      </geometry>
      <origin xyz="0 0 0" rpy="0 0 0" />
    </collision>
    <inertial>
      <origin xyz="0 0 0.003" rpy="0 0 0" />
      <mass value="0.01" />
      <xacro:cylinder_inertia m="0.01" r="0.05" h="0.006" />
    </inertial> 
  </link>

  
  <xacro:property name="mycobot_origin" value="0 0 0.09" />
  <xacro:mycobot_robot prefix="" parent="arm_base_link">
    <origin xyz="${mycobot_origin}" rpy="0 0 0" />
  </xacro:mycobot_robot> 
    
  
  <xacro:if value="$(arg gazebo_plugin)">
    <gazebo>
      <plugin name="gazebo_ros_control" filename="libgazebo_ros_control.so">
        <robotNamespace>$(arg robot_namespace)</robotNamespace>
        <robotSimType>gazebo_ros_control/DefaultRobotHWSim</robotSimType>
        <legacyModeNS>false</legacyModeNS>
      </plugin>
    </gazebo>
  </xacro:if>
  -->
  
    
</robot>



