<?xml version="1.0"?>
<robot xmlns:xacro="http://ros.org/wiki/xacro">

  <xacro:include filename="$(find mycobot_description)/urdf/common.xacro" />
  <!--<xacro:include filename="$(find mycobot_description)/urdf/color.xacro" />-->

  <xacro:macro name="mycobot_robot" params="prefix parent *joint_origin">

    <xacro:property name="mycobot_link_1" value="${prefix}link1" />
    <xacro:property name="mycobot_link_2" value="${prefix}link2" />
    <xacro:property name="mycobot_link_3" value="${prefix}link3" />
    <xacro:property name="mycobot_link_4" value="${prefix}link4" />
    <xacro:property name="mycobot_link_5" value="${prefix}link5" />
    <xacro:property name="mycobot_link_6" value="${prefix}link6" />
    <xacro:property name="mycobot_link_7" value="${prefix}link6_flange" />
    <xacro:property name="mycobot_joint_1" value="${prefix}joint1" />
    <xacro:property name="mycobot_joint_2" value="${prefix}joint2" />
    <xacro:property name="mycobot_joint_3" value="${prefix}joint3" />
    <xacro:property name="mycobot_joint_4" value="${prefix}joint4" />
    <xacro:property name="mycobot_joint_5" value="${prefix}joint5" />
    <xacro:property name="mycobot_joint_6" value="${prefix}joint6" />

    <xacro:property name="joint_velocity_limit" value="1.0" />


    <joint name="arm_base_joint" type="fixed">
      <xacro:insert_block name="joint_origin" />
      <parent link="${parent}" />
      <child link="${mycobot_link_1}" />
    </joint>

    <link name="${mycobot_link_1}">
      <visual>
        <geometry>
          <mesh filename="package://mycobot_description/meshes/stl/visual/link1.stl" />
        </geometry>
        <origin xyz="0 0 0" rpy="0 0 0" />
        <material name="white" />
      </visual>
      <collision>
        <geometry>
          <mesh filename="package://mycobot_description/meshes/stl/collision/link1.stl" />
          <!-- <mesh filename="package://mycobot_description/meshes/stl/visual/link1.stl" /> -->
        </geometry>
        <origin xyz="0 0 0" rpy="0 0 0" />
      </collision>
      <inertial>
        <origin xyz="0 0 0.035" rpy="0 0 0" />
        <mass value="1.0" />
        <xacro:cylinder_inertia m="1.0" r="0.05" h="0.07" />
      </inertial>
    </link>

    <link name="${mycobot_link_2}">
      <visual>
        <geometry>
          <mesh filename="package://mycobot_description/meshes/stl/visual/link2.stl" />
        </geometry>
        <origin xyz="0 0 0" rpy="0 0 0" />
        <material name="white" />
      </visual>
      <collision>
        <geometry>
          <mesh filename="package://mycobot_description/meshes/stl/collision/link2.stl" />
          <!-- <mesh filename="package://mycobot_description/meshes/stl/visual/link2.stl" /> -->
        </geometry>
        <origin xyz="0 0 0" rpy="0 0 0" />
      </collision>
      <inertial>
        <origin xyz="0 0 0.060" rpy="0 0 0" />
        <mass value="0.2" />
        <xacro:cylinder_inertia m="0.2" r="0.05" h="0.08" />
      </inertial>
    </link>

    <link name="${mycobot_link_3}">
      <visual>
        <geometry>
          <mesh filename="package://mycobot_description/meshes/stl/visual/link3.stl" />
        </geometry>
        <origin xyz="0 0 0" rpy="0 0 0" />
        <material name="white" />
      </visual>
      <collision>
        <geometry>
          <mesh filename="package://mycobot_description/meshes/stl/collision/link3.stl" />
          <!-- <mesh filename="package://mycobot_description/meshes/stl/visual/link3.stl" /> -->
        </geometry>
        <origin xyz="0 0 0" rpy="0 0 0" />
      </collision>
      <inertial>
        <origin xyz="0.01 0 0.06" rpy="0 0 0" />
        <mass value="0.4" />
        <xacro:cylinder_inertia m="0.4" r="0.05" h="0.155" />
      </inertial>
    </link>

    <link name="${mycobot_link_4}">
      <visual>
        <geometry>
          <mesh filename="package://mycobot_description/meshes/stl/visual/link4.stl" />
        </geometry>
        <origin xyz="0 0 0" rpy="0 0 0" />
        <material name="white" />
      </visual>
      <collision>
        <geometry>
          <mesh filename="package://mycobot_description/meshes/stl/collision/link4.stl" />
          <!-- <mesh filename="package://mycobot_description/meshes/stl/visual/link4.stl" /> -->
        </geometry>
        <origin xyz="0 0 0" rpy="0 0 0" />
      </collision>
      <inertial>
        <origin xyz="-0.01 0 0.05" rpy="0 0 0" />
        <mass value="0.4" />
        <xacro:cylinder_inertia m="0.4" r="0.05" h="0.155" />
      </inertial>
    </link>

    <link name="${mycobot_link_5}">
      <visual>
        <geometry>
          <mesh filename="package://mycobot_description/meshes/stl/visual/link5.stl" />
        </geometry>
        <origin xyz="0 0 0" rpy="0 0 0" />
        <material name="white" />
      </visual>
      <collision>
        <geometry>
          <mesh filename="package://mycobot_description/meshes/stl/collision/link5.stl" />
          <!-- <mesh filename="package://mycobot_description/meshes/stl/visual/link5.stl" /> -->
        </geometry>
        <origin xyz="0 0 0" rpy="0 0 0" />
      </collision>
      <inertial>
        <origin xyz="0 0 0.05" rpy="0 0 0" />
        <mass value="0.2" />
        <xacro:cylinder_inertia m="0.2" r="0.05" h="0.05" />
      </inertial>
    </link>

    <link name="${mycobot_link_6}">
      <visual>
        <geometry>
          <mesh filename="package://mycobot_description/meshes/stl/visual/link6.stl" />
        </geometry>
        <origin xyz="0 0 0 " rpy="0 0 0" />
        <material name="white" />
      </visual>
      <collision>
        <geometry>
          <mesh filename="package://mycobot_description/meshes/stl/collision/link6.stl" />
          <!-- <mesh filename="package://mycobot_description/meshes/stl/visual/link6.stl" /> -->
        </geometry>
        <origin xyz="0 0 0" rpy="0 0 0" />
      </collision>
      <inertial>
        <origin xyz="0 0 0.037" rpy="0 0 0" />
        <mass value="0.5" />
        <xacro:cylinder_inertia m="0.5" r="0.05" h="0.06" />
      </inertial>
    </link>

    <link name="${mycobot_link_7}">
      <visual>
        <geometry>
          <cylinder length="0.005" radius="0.02" />
        </geometry>
        <origin xyz="0 0.0025 0" rpy="${M_PI/2} 0 0" />
        <material name="white" />
      </visual>
      <collision>
        <geometry>
          <cylinder length="0.005" radius="0.02" />
        </geometry>
        <origin xyz="0 0.0025 0" rpy="${M_PI/2} 0 0" />
      </collision>
      <inertial>
        <origin xyz="0 0.0025 0" rpy="${M_PI/2} 0 0" />
        <mass value="0.1" />
        <xacro:cylinder_inertia m="0.1" r="0.02" h="0.005" />
      </inertial>
    </link>

    <joint name="${mycobot_joint_1}" type="revolute">
      <axis xyz="0 0 1" />
      <limit effort="10.0" lower="-${M_PI}" upper="${M_PI}" velocity="${joint_velocity_limit}" />
      <parent link="${mycobot_link_1}" />
      <child link="${mycobot_link_2}" />
      <origin xyz="0 0 0.0706" rpy="0 0 0" />
      <dynamics damping="1.0e-6" friction="2.0e-1" />
    </joint>

    <joint name="${mycobot_joint_2}" type="revolute">
      <axis xyz="1 0 0" />
      <limit effort="10.0" lower="-${M_PI}" upper="${M_PI}" velocity="${joint_velocity_limit}" />
      <parent link="${mycobot_link_2}" />
      <child link="${mycobot_link_3}" />
      <origin xyz="0.03256 0 0.05976" rpy="0 0 0" />
      <dynamics damping="1.0e-6" friction="2.0e-1" />
    </joint>

    <joint name="${mycobot_joint_3}" type="revolute">
      <axis xyz="1 0 0" />
      <limit effort="10.0" lower="-${M_PI}" upper="${M_PI}" velocity="${joint_velocity_limit}" />
      <parent link="${mycobot_link_3}" />
      <child link="${mycobot_link_4}" />
      <origin xyz=" 0.00272 0 0.1104" rpy="0 0 0" />
      <dynamics damping="1.0e-6" friction="2.0e-1" />
    </joint>

    <joint name="${mycobot_joint_4}" type="revolute">
      <axis xyz="1 0 0" />
      <limit effort="10.0" lower="-${M_PI}" upper="${M_PI}" velocity="${joint_velocity_limit}" />
      <parent link="${mycobot_link_4}" />
      <child link="${mycobot_link_5}" />
      <origin xyz="-0.00164 0 0.096" rpy="0 0 0" />
      <dynamics damping="1.0e-6" friction="2.0e-1" />
    </joint>

    <joint name="${mycobot_joint_5}" type="revolute">
      <axis xyz="0 0 1" />
      <limit effort="10.0" lower="-${M_PI}" upper="${M_PI}" velocity="${joint_velocity_limit}" />
      <parent link="${mycobot_link_5}" />
      <child link="${mycobot_link_6}" />
      <origin xyz="0.0298 0 0.02876" rpy="0 0 0" />
      <dynamics damping="1.0e-6" friction="2.0e-1" />
    </joint>

    <joint name="${mycobot_joint_6}" type="revolute">
      <axis xyz="0 1 0" />
      <limit effort="10.0" lower="-${M_PI}" upper="${M_PI}" velocity="${joint_velocity_limit}" />
      <parent link="${mycobot_link_6}" />
      <child link="${mycobot_link_7}" />
      <origin xyz="0 0.0456 0.03792" rpy="0 0 0" />
      <dynamics damping="1.0e-6" friction="2.0e-1" />
    </joint>
    
    
  <!-- GRIPPER -->
  <!--
   <joint name="joint6output_to_gripper_base" type="fixed">
        <parent link="${mycobot_link_7}" />
        <child link="gripper_base" />
        <origin xyz="0 0.0 0.034" rpy="0 0 0" />
    </joint>
    
    <link name="gripper_base">
        <visual>
            <geometry>

                <mesh filename="package://mycobot_description/urdf/320_urdf/gripper_base.dae" />
            </geometry>
            <origin xyz="-0.02 0.012 -0.018 " rpy=" 0 0 1.5708" />
        </visual>
        <collision>
            <geometry>

                <mesh filename="package://mycobot_description/urdf/320_urdf/gripper_base.dae" />
            </geometry>
            <origin xyz="-0.02 0.012 -0.018 " rpy=" 0 0 1.5708" />
        </collision>
        <inertial>
            <mass value="0.1" />
            <origin xyz="0 0 0" rpy="0 0 0" />
            <inertia ixx="0.03" iyy="0.03" izz="0.03" ixy="0.0" ixz="0.0" iyz="0.0" />
        </inertial>
    </link>
  
    <joint name="gripper_controller" type="revolute">
        <axis xyz="0 0 1" />
        <limit effort="1000.0" lower="-0.7" upper="0.3" velocity="0" />
        <parent link="gripper_base" />
        <child link="gripper_left3" />
        <origin xyz="-0.018 0.016 0" rpy="0 0 0" />
    </joint>
    <link name="gripper_left3">
        <visual>
            <geometry>
                <mesh filename="package://mycobot_description/urdf/320_urdf/gripper_left3.dae" />
            </geometry>
            <origin xyz="0.034 0.0 -0.012 " rpy=" 0 3.14159 -1.5708" />

        </visual>
        <collision>
            <geometry>
                <mesh filename="package://mycobot_description/urdf/320_urdf/gripper_left3.dae" />
            </geometry>
            <origin xyz="0.034 0.0 -0.012 " rpy=" 0 3.14159 -1.5708" />
        </collision>
        <inertial>
            <mass value="0.1" />
            <origin xyz="0 0 0" rpy="0 0 0" />
            <inertia ixx="0.03" iyy="0.03" izz="0.03" ixy="0.0" ixz="0.0" iyz="0.0" />
        </inertial>
    </link>    
    
    <joint name="gripper_base_to_gripper_left2" type="revolute">
        <axis xyz="0 0 1" />
        <limit effort="1000.0" lower="-0.8" upper="0.5" velocity="0" />
        <parent link="gripper_base" />
        <child link="gripper_left2" />
        <origin xyz="-0.05 -0.01 0" rpy="0 0 0" />
        <mimic joint="gripper_controller" multiplier="1.0" offset="0" />
    </joint>
    
    <link name="gripper_left2">
        <visual>
            <geometry>
                <mesh filename="package://mycobot_description/urdf/320_urdf/gripper_left2.dae" />
            </geometry>
            <origin xyz="0.03 0.024 -0.018 " rpy=" 0 0 1.5708" />
        </visual>
        <collision>
            <geometry>
                <mesh filename="package://mycobot_description/urdf/320_urdf/gripper_left2.dae" />
            </geometry>
            <origin xyz="0.03 0.024 -0.018 " rpy=" 0 0 1.5708" />
        </collision>
        <inertial>
            <mass value="0.1" />
            <origin xyz="0 0 0" rpy="0 0 0" />
            <inertia ixx="0.03" iyy="0.03" izz="0.03" ixy="0.0" ixz="0.0" iyz="0.0" />
        </inertial>
    </link>    
    
    <joint name="gripper_left3_to_gripper_left1" type="revolute">
        <axis xyz="0 0 1" />
        <limit effort="1000.0" lower="-0.5" upper="0.5" velocity="0" />
        <parent link="gripper_left3" />
        <child link="gripper_left1" />
        <origin xyz="-0.0356 0.051 -0.018" rpy="0 0 0" />
        <mimic joint="gripper_controller" multiplier="-1.0" offset="0" />
    </joint>
    
    <link name="gripper_left1">
        <visual>
            <geometry>

                <mesh filename="package://mycobot_description/urdf/320_urdf/gripper_left1.dae" />
            </geometry>
            <origin xyz="0.036 -0.052 0.0 " rpy=" 0 0 1.5708" />
        </visual>
        <collision>
            <geometry>
                <mesh filename="package://mycobot_description/urdf/320_urdf/gripper_left1.dae" />
            </geometry>
            <origin xyz="0.036 -0.052 0.0 " rpy=" 0 0 1.5708" />
        </collision>
        <inertial>
            <mass value="0.1" />
            <origin xyz="0 0 0" rpy="0 0 0" />
            <inertia ixx="0.03" iyy="0.03" izz="0.03" ixy="0.0" ixz="0.0" iyz="0.0" />
        </inertial>
    </link>
    
    <joint name="gripper_base_to_gripper_right3" type="revolute">
        <axis xyz="0 0 1" />
        <limit effort="1000.0" lower="-0.3" upper="0.7" velocity="0" />
        <parent link="gripper_base" />
        <child link="gripper_right3" />
        <origin xyz="0.018 0.016 0" rpy="0 0 0" />
        <mimic joint="gripper_controller" multiplier="-1.0" offset="0" />
    </joint>
    
    <link name="gripper_right3">
        <visual>
            <geometry>
                <mesh filename="package://mycobot_description/urdf/320_urdf/gripper_right3.dae" />
            </geometry>
            <origin xyz="0 0.0 -0.012 " rpy=" 0 3.14159 -1.5708" />
        </visual>
        <collision>
            <geometry>
                <mesh filename="package://mycobot_description/urdf/320_urdf/gripper_right3.dae" />
            </geometry>
            <origin xyz="-0.034 0.0 -0.012 " rpy=" 0 3.14159 -1.5708" />
        </collision>
        <inertial>
            <mass value="0.1" />
            <origin xyz="0 0 0" rpy="0 0 0" />
            <inertia ixx="0.03" iyy="0.03" izz="0.03" ixy="0.0" ixz="0.0" iyz="0.0" />
        </inertial>
    </link>    
    
    <joint name="gripper_base_to_gripper_right2" type="revolute">
        <axis xyz="0 0 1" />
        <limit effort="1000.0" lower="-0.5" upper="0.8" velocity="0" />
        <parent link="gripper_base" />
        <child link="gripper_right2" />
        <origin xyz="0.046 -0.01 0" rpy="0 0 0" />
        <mimic joint="gripper_controller" multiplier="-1.0" offset="0" />
    </joint>
    
    <link name="gripper_right2">
        <visual>
            <geometry>
                <mesh filename="package://mycobot_description/urdf/320_urdf/gripper_right2.dae" />
            </geometry>
            <origin xyz="-0.066 0.023 -0.018 " rpy=" 0 0 1.5708" />
        </visual>
        <collision>
            <geometry>
                <mesh filename="package://mycobot_description/urdf/320_urdf/gripper_right2.dae" />
            </geometry>
            <origin xyz="-0.03 0.024 -0.018 " rpy=" 0 0 1.5708" />
        </collision>
        <inertial>
            <mass value="0.1" />
            <origin xyz="0 0 0" rpy="0 0 0" />
            <inertia ixx="0.03" iyy="0.03" izz="0.03" ixy="0.0" ixz="0.0" iyz="0.0" />
        </inertial>
    </link>    
    
    <joint name="gripper_right3_to_gripper_right1" type="revolute">
        <axis xyz="0 0 1" />
        <limit effort="1000.0" lower="-0.5" upper="0.5" velocity="0" />
        <parent link="gripper_right3" />
        <child link="gripper_right1" />
        <origin xyz="0.033 0.051 -0.018" rpy="0 0 0" />
        <mimic joint="gripper_controller" multiplier="1.0" offset="0" />
    </joint>

    <link name="gripper_right1">
        <visual>
            <geometry>

                <mesh filename="package://mycobot_description/urdf/320_urdf/gripper_right1.dae" />
            </geometry>
            <origin xyz="-0.072 -0.05 0.0 " rpy=" 0 0 1.5708" />
        </visual>
        <collision>
            <geometry>
                <mesh filename="package://mycobot_description/urdf/320_urdf/gripper_right1.dae" />
            </geometry>
            <origin xyz="-0.036 -0.052 0.0 " rpy=" 0 0 1.5708" />
        </collision>
        <inertial>
            <mass value="0.1" />
            <origin xyz="0 0 0" rpy="0 0 0" />
            <inertia ixx="0.03" iyy="0.03" izz="0.03" ixy="0.0" ixz="0.0" iyz="0.0" />
        </inertial>
    </link>
    -->


    

    <!-- for gazebo simulation -->


      <transmission name="${mycobot_joint_1}_trans">
        <provideFeedback>true</provideFeedback>
        <implicitSpringDamper>0</implicitSpringDamper>
        <motorTorqueConstant>0.418</motorTorqueConstant>
        <type>transmission_interface/SimpleTransmission</type>
        <joint name="${mycobot_joint_1}">
          <hardwareInterface>hardware_interface/PositionJointInterface</hardwareInterface>
        </joint>
        <actuator name="${mycobot_joint_1}_motor">
          <hardwareInterface>hardware_interface/PositionJointInterface</hardwareInterface>
          <mechanicalReduction>1</mechanicalReduction>
        </actuator>
      </transmission>
      <transmission name="${mycobot_joint_2}_trans">
        <provideFeedback>true</provideFeedback>
        <implicitSpringDamper>0</implicitSpringDamper>
        <motorTorqueConstant>0.418</motorTorqueConstant>
        <type>transmission_interface/SimpleTransmission</type>
        <joint name="${mycobot_joint_2}">
          <hardwareInterface>hardware_interface/PositionJointInterface</hardwareInterface>
        </joint>
        <actuator name="${mycobot_joint_2}_motor">
          <hardwareInterface>hardware_interface/PositionJointInterface</hardwareInterface>
          <mechanicalReduction>1</mechanicalReduction>
        </actuator>
      </transmission>
      <transmission name="${mycobot_joint_3}_trans">
        <provideFeedback>true</provideFeedback>
        <implicitSpringDamper>0</implicitSpringDamper>
        <motorTorqueConstant>0.418</motorTorqueConstant>
        <type>transmission_interface/SimpleTransmission</type>
        <joint name="${mycobot_joint_3}">
          <hardwareInterface>hardware_interface/PositionJointInterface</hardwareInterface>
        </joint>
        <actuator name="${mycobot_joint_3}_motor">
          <hardwareInterface>hardware_interface/PositionJointInterface</hardwareInterface>
          <mechanicalReduction>1</mechanicalReduction>
        </actuator>
      </transmission>
      <transmission name="${mycobot_joint_4}_trans">
        <provideFeedback>true</provideFeedback>
        <implicitSpringDamper>0</implicitSpringDamper>
        <motorTorqueConstant>0.418</motorTorqueConstant>
        <type>transmission_interface/SimpleTransmission</type>
        <joint name="${mycobot_joint_4}">
          <hardwareInterface>hardware_interface/PositionJointInterface</hardwareInterface>
        </joint>
        <actuator name="${mycobot_joint_4}_motor">
          <hardwareInterface>hardware_interface/PositionJointInterface</hardwareInterface>
          <mechanicalReduction>1</mechanicalReduction>
        </actuator>
      </transmission>
      <transmission name="${mycobot_joint_5}_trans">
        <provideFeedback>true</provideFeedback>
        <implicitSpringDamper>0</implicitSpringDamper>
        <motorTorqueConstant>0.418</motorTorqueConstant>
        <type>transmission_interface/SimpleTransmission</type>
        <joint name="${mycobot_joint_5}">
          <hardwareInterface>hardware_interface/PositionJointInterface</hardwareInterface>
        </joint>
        <actuator name="${mycobot_joint_5}_motor">
          <hardwareInterface>hardware_interface/PositionJointInterface</hardwareInterface>
          <mechanicalReduction>1</mechanicalReduction>
        </actuator>
      </transmission>
      <transmission name="${mycobot_joint_6}_trans">
        <provideFeedback>true</provideFeedback>
        <implicitSpringDamper>0</implicitSpringDamper>
        <motorTorqueConstant>0.418</motorTorqueConstant>
        <type>transmission_interface/SimpleTransmission</type>
        <joint name="${mycobot_joint_6}">
          <hardwareInterface>hardware_interface/PositionJointInterface</hardwareInterface>
        </joint>
        <actuator name="${mycobot_joint_6}_motor">
          <hardwareInterface>hardware_interface/PositionJointInterface</hardwareInterface>
          <mechanicalReduction>1</mechanicalReduction>
        </actuator>
      </transmission>
      

     <!-- *** GRIPPER *** -->
     <!--
     <transmission name="trans_gripper_controller">
        <type>transmission_interface/SimpleTransmission</type>
        <joint name="gripper_controller">
            <hardwareInterface>hardware_interface/EffortJointInterface</hardwareInterface>
        </joint>
        <actuator name="gripper_controller_motor">
            <hardwareInterface>hardware_interface/EffortJointInterface</hardwareInterface>
            <mechanicalReduction>1</mechanicalReduction>
        </actuator>
    </transmission>
    <transmission name="trans_gripper_base_to_gripper_left2">
        <type>transmission_interface/SimpleTransmission</type>
        <joint name="gripper_base_to_gripper_left2">
            <hardwareInterface>hardware_interface/EffortJointInterface</hardwareInterface>
        </joint>
        <actuator name="gripper_base_to_gripper_left2_motor">
            <hardwareInterface>hardware_interface/EffortJointInterface</hardwareInterface>
            <mechanicalReduction>1</mechanicalReduction>
        </actuator>
    </transmission>
    <transmission name="trans_gripper_left3_to_gripper_left1">
        <type>transmission_interface/SimpleTransmission</type>
        <joint name="gripper_left3_to_gripper_left1">
            <hardwareInterface>hardware_interface/EffortJointInterface</hardwareInterface>
        </joint>
        <actuator name="gripper_left3_to_gripper_left1_motor">
            <hardwareInterface>hardware_interface/EffortJointInterface</hardwareInterface>
            <mechanicalReduction>1</mechanicalReduction>
        </actuator>
    </transmission>
    <transmission name="trans_gripper_base_to_gripper_right3">
        <type>transmission_interface/SimpleTransmission</type>
        <joint name="gripper_base_to_gripper_right3">
            <hardwareInterface>hardware_interface/EffortJointInterface</hardwareInterface>
        </joint>
        <actuator name="gripper_base_to_gripper_right3_motor">
            <hardwareInterface>hardware_interface/EffortJointInterface</hardwareInterface>
            <mechanicalReduction>1</mechanicalReduction>
        </actuator>
    </transmission>
    <transmission name="trans_gripper_base_to_gripper_right2">
        <type>transmission_interface/SimpleTransmission</type>
        <joint name="gripper_base_to_gripper_right2">
            <hardwareInterface>hardware_interface/EffortJointInterface</hardwareInterface>
        </joint>
        <actuator name="gripper_base_to_gripper_right2_motor">
            <hardwareInterface>hardware_interface/EffortJointInterface</hardwareInterface>
            <mechanicalReduction>1</mechanicalReduction>
        </actuator>
    </transmission>
    <transmission name="trans_gripper_right3_to_gripper_right1">
        <type>transmission_interface/SimpleTransmission</type>
        <joint name="gripper_right3_to_gripper_right1">
            <hardwareInterface>hardware_interface/EffortJointInterface</hardwareInterface>
        </joint>
        <actuator name="gripper_right3_to_gripper_right1_motor">
            <hardwareInterface>hardware_interface/EffortJointInterface</hardwareInterface>
            <mechanicalReduction>1</mechanicalReduction>
        </actuator>
    </transmission>
    -->
    <!-- **** -->    
 


      <gazebo reference="${mycobot_link_1}">
        <material>Gazebo/White</material>
      </gazebo>

      <gazebo reference="${mycobot_link_2}">
        <material>Gazebo/White</material>
      </gazebo>

      <gazebo reference="${mycobot_link_3}">
        <material>Gazebo/White</material>
      </gazebo>

      <gazebo reference="${mycobot_link_4}">
        <material>Gazebo/White</material>
      </gazebo>

      <gazebo reference="${mycobot_link_5}">
        <material>Gazebo/White</material>
      </gazebo>

      <gazebo reference="${mycobot_link_6}">
        <material>Gazebo/White</material>
      </gazebo>

  </xacro:macro>
</robot>
